Fixed issue where reading a datetime column containing ``pd.NaT`` values would throw an ``OutOfBoundsDatetime`` error
